Workbook
Name Slicer_Gateway: #N/A
Name Slicer_Payment_Method: #N/A
Name Slicer_Date: #N/A
Name Slicer_Institute_Name: #N/A

Sheet Raw_Data
A1: Sr.No | B1: Institute Name | C1: Date & Time | D1: Order ID | E1: Edviron order ID | F1: Order Amt | G1: Transaction Amt | H1: Payment Method | I1: payment_mode | J1: Status | K1: Student Name | L1: Phone No. | M1: Vendor Amount | N1: Gateway | O1: Capture Status | P1: Merchant Pricing | Q1: Merchant Pricing Type | R1: Partner Pricing | S1: Partner Pricing Type | T1: Edviron Buying | U1: Edviron Buying type
A2: 1 | B2: SBNM College of Pharmacy (D. Pharmacy & B.Pharmarcy | C2: 1/4/2025, 12:31:47 PM | D2: EDVI0000002711 | E2: 67eb8f5ba0b8c5db0650bf9c | F2: 3800 | G2: 3802.36 | H2: upi | I2: UPI | J2: SUCCESS | K2: RushikeshPatil | M2: NA | N2: CASHFREE | P2: 2 | Q2: FLAT | R2: 2 | S2: FLAT | T2: 0 | U2: FLAT
A3: 2 | B3: R P College of Pharmacy | C3: 11/4/2025, 11:51:49 AM | D3: EDVI0000002716 | E3: 67f8b4fdb7b5f003daf0968e | F3: 15000 | G3: 15002.36 | H3: upi | I3: UPI | J3: SUCCESS | K3: Pranav Prakash Deshpande | M3: NA | N3: CASHFREE | P3: 2 | Q3: FLAT | R3: 2 | S3: FLAT | T3: 0 | U3: FLAT
A4: 3 | B4: R P College of Pharmacy | C4: 21/4/2025, 10:31:19 am | D4: EDVI0000002722 | E4: 6805d11f8218d3a8c0364231 | F4: 10000 | G4: 10002.36 | H4: upi | I4: UPI | J4: SUCCESS | K4: Dattatray Uttam Gholve | M4: NA | N4: CASHFREE | P4: 2 | Q4: FLAT | R4: 2 | S4: FLAT | T4: 0 | U4: FLAT
A5: 4 | B5: R P College of Pharmacy | C5: 29/4/2025, 11:10:54 am | D5: EDVI0000002724 | E5: 681066668dde280c7a057a3a | F5: 5000 | G5: 5002.36 | H5: upi | I5: UPI | J5: SUCCESS | K5: Saniya Wajid Shaikh | M5: NA | N5: CASHFREE | P5: 2 | Q5: FLAT | R5: 2 | S5: FLAT | T5: 0 | U5: FLAT
A6: 5 | B6: R P College of Pharmacy | C6: 29/4/2025, 11:14:19 am | D6: EDVI0000002725 | E6: 68106733d4b7fd07d305e50a | F6: 5000 | G6: 5002.36 | H6: upi | I6: UPI | J6: SUCCESS | K6: Pooja subhashprasad shukla | M6: NA | N6: CASHFREE | P6: 2 | Q6: FLAT | R6: 2 | S6: FLAT | T6: 0 | U6: FLAT
A7: 6 | B7: R P College of Pharmacy | C7: 30/4/2025, 1:53:35 pm | D7: EDVI0000004024 | E7: 6811de07d4b7fd07d306cb37 | F7: 10000 | G7: 10002.36 | H7: upi | I7: UPI | J7: SUCCESS | K7: BEGADE HALIMA BADSHAHA | M7: NA | N7: CASHFREE | P7: 2 | Q7: FLAT | R7: 2 | S7: FLAT | T7: 0 | U7: FLAT
A8: 7 | B8: R P College of Pharmacy | C8: 30/4/2025, 2:03:25 pm | D8: EDVI0000004025 | E8: 6811e055d4b7fd07d306ceed | F8: 18836 | G8: 18838.36 | H8: upi | I8: UPI | J8: SUCCESS | K8: JADHAV GAURAV SANTOSH | M8: NA | N8: CASHFREE | P8: 2 | Q8: FLAT | R8: 2 | S8: FLAT | T8: 0 | U8: FLAT
A9: 1 | B9: R P College of Pharmacy | C9: 14/6/2025, 11:24:42 am | D9: EDVI0000004079 | E9: 684d0ea2b1091c01feb8de58 | F9: 10576 | G9: 10578.36 | H9: upi | I9: Others | J9: SUCCESS | K9: SOHAM SAGAR KHOT | M9: NA | N9: CASHFREE | P9: 2 | Q9: FLAT | R9: 2 | S9: FLAT | T9: 0 | U9: FLAT
A10: 2 | B10: R P College of Pharmacy | C10: 7/7/2025, 4:08:10 PM | D10: EDVI0000004105 | E10: 686ba3924e76b124b7acdd57 | F10: 1 | G10: 3.36 | H10: upi | I10: Others | J10: SUCCESS | K10: Test Student | M10: NA | N10: CASHFREE | P10: 2 | Q10: FLAT | R10: 2 | S10: FLAT | T10: 0 | U10: FLAT
A11: 6 | B11: ST MICHAEL'S SCHOOL FOR GIRLS | C11: 14/11/2025, 10:46:26 am | D11: SMED0000000331 | E11: 6916bb2afede88bc173e1480 | F11: 34325 | G11: 34327.36 | H11: upi | I11: Others | J11: SUCCESS | K11: RUDRANI SENGUPTA | M11: NA | N11: EDVIRON_EASEBUZZ | P11: 2 | Q11: FLAT | R11: 2 | S11: FLAT | T11: 0 | U11: FLAT
A12: 8 | B12: ST MICHAEL'S SCHOOL FOR GIRLS | C12: 30/11/2025, 2:29:11 pm | D12: SMED0000000337 | E12: 692c075f09edb37dee1521c4 | F12: 38100 | G12: 38102.36 | H12: upi | I12: Others | J12: SUCCESS | K12: VASUDHA ALOK | M12: NA | N12: EDVIRON_EASEBUZZ | P12: 2 | Q12: FLAT | R12: 2 | S12: FLAT | T12: 0 | U12: FLAT
A13: 1 | B13: ST MICHAEL'S SCHOOL FOR GIRLS | C13: 1/12/2025, 1:41:08 PM | D13: SMED0000000339 | E13: 692d4d9c4b29e4e74d7d73d4 | F13: 10350 | G13: 10352.36 | H13: upi | I13: - | J13: SUCCESS | K13: SHRITI SHARMA | M13: NA | N13: EDVIRON_EASEBUZZ | P13: 2 | Q13: FLAT | R13: 2 | S13: FLAT | T13: 0 | U13: FLAT
... A38: 30 | B38: ST MICHAEL'S SCHOOL FOR GIRLS | C38: 29/1/2026, 9:34:31 pm | D38: SMED0000000460 | E38: 697b850f0a91fbff417eab30 | F38: 34325 | G38: 34327.36 | H38: upi | I38: Others | J38: success | K38: AADHYA DAS | M38: NA | N38: EDVIRON_EASEBUZZ | P38: 2 | Q38: FLAT | R38: 2 | S38: FLAT | T38: 0 | U38: FLAT

Sheet Clean_data
A1: Sl.No | B1: Institute Name | C1: Date & Time | D1: Order ID | E1: Edviron order ID | F1: Order Amt | G1: Transaction Amt | H1: Payment Method | I1: payment_mode | J1: Status | K1: Student Name | L1: Phone No. | M1: Vendor Amount | N1: Gateway | O1: Capture Status | P1: Merchant Pricing | Q1: Merchant Pricing Type | R1: Partner Pricing | S1: Partner Pricing Type | T1: Edviron Buying | U1: Edviron Buying type
A2: 1 | B2: SBNM College of Pharmacy (D. Pharmacy & B.Pharmarcy | C2: 1/4/2025, 12:31:47 PM | D2: EDVI0000002711 | E2: 67eb8f5ba0b8c5db0650bf9c | F2: 3800 | G2: 3802.36 | H2: upi | I2: UPI | J2: SUCCESS | K2: RushikeshPatil | M2: 0 | N2: CASHFREE | P2: 2 | Q2: FLAT | R2: 2 | S2: FLAT | T2: 0 | U2: FLAT
A3: 2 | B3: R P College of Pharmacy | C3: 11/4/2025, 11:51:49 AM | D3: EDVI0000002716 | E3: 67f8b4fdb7b5f003daf0968e | F3: 15000 | G3: 15002.36 | H3: upi | I3: UPI | J3: SUCCESS | K3: Pranav Prakash Deshpande | M3: 0 | N3: CASHFREE | P3: 2 | Q3: FLAT | R3: 2 | S3: FLAT | T3: 0 | U3: FLAT
A4: 3 | B4: R P College of Pharmacy | C4: 21/4/2025, 10:31:19 am | D4: EDVI0000002722 | E4: 6805d11f8218d3a8c0364231 | F4: 10000 | G4: 10002.36 | H4: upi | I4: UPI | J4: SUCCESS | K4: Dattatray Uttam Gholve | M4: 0 | N4: CASHFREE | P4: 2 | Q4: FLAT | R4: 2 | S4: FLAT | T4: 0 | U4: FLAT
A5: 4 | B5: R P College of Pharmacy | C5: 29/4/2025, 11:10:54 am | D5: EDVI0000002724 | E5: 681066668dde280c7a057a3a | F5: 5000 | G5: 5002.36 | H5: upi | I5: UPI | J5: SUCCESS | K5: Saniya Wajid Shaikh | M5: 0 | N5: CASHFREE | P5: 2 | Q5: FLAT | R5: 2 | S5: FLAT | T5: 0 | U5: FLAT
A6: 5 | B6: R P College of Pharmacy | C6: 29/4/2025, 11:14:19 am | D6: EDVI0000002725 | E6: 68106733d4b7fd07d305e50a | F6: 5000 | G6: 5002.36 | H6: upi | I6: UPI | J6: SUCCESS | K6: Pooja subhashprasad shukla | M6: 0 | N6: CASHFREE | P6: 2 | Q6: FLAT | R6: 2 | S6: FLAT | T6: 0 | U6: FLAT
A7: 6 | B7: R P College of Pharmacy | C7: 30/4/2025, 1:53:35 pm | D7: EDVI0000004024 | E7: 6811de07d4b7fd07d306cb37 | F7: 10000 | G7: 10002.36 | H7: upi | I7: UPI | J7: SUCCESS | K7: BEGADE HALIMA BADSHAHA | M7: 0 | N7: CASHFREE | P7: 2 | Q7: FLAT | R7: 2 | S7: FLAT | T7: 0 | U7: FLAT
A8: 7 | B8: R P College of Pharmacy | C8: 30/4/2025, 2:03:25 pm | D8: EDVI0000004025 | E8: 6811e055d4b7fd07d306ceed | F8: 18836 | G8: 18838.36 | H8: upi | I8: UPI | J8: SUCCESS | K8: JADHAV GAURAV SANTOSH | M8: 0 | N8: CASHFREE | P8: 2 | Q8: FLAT | R8: 2 | S8: FLAT | T8: 0 | U8: FLAT
A9: 8 | B9: R P College of Pharmacy | C9: 14/6/2025, 11:24:42 am | D9: EDVI0000004079 | E9: 684d0ea2b1091c01feb8de58 | F9: 10576 | G9: 10578.36 | H9: upi | I9: Others | J9: SUCCESS | K9: SOHAM SAGAR KHOT | M9: 0 | N9: CASHFREE | P9: 2 | Q9: FLAT | R9: 2 | S9: FLAT | T9: 0 | U9: FLAT
A10: 9 | B10: R P College of Pharmacy | C10: 7/7/2025, 4:08:10 PM | D10: EDVI0000004105 | E10: 686ba3924e76b124b7acdd57 | F10: 1 | G10: 3.36 | H10: upi | I10: Others | J10: SUCCESS | K10: Test Student | M10: 0 | N10: CASHFREE | P10: 2 | Q10: FLAT | R10: 2 | S10: FLAT | T10: 0 | U10: FLAT
A11: 10 | B11: ST MICHAEL'S SCHOOL FOR GIRLS | C11: 14/11/2025, 10:46:26 am | D11: SMED0000000331 | E11: 6916bb2afede88bc173e1480 | F11: 34325 | G11: 34327.36 | H11: upi | I11: Others | J11: SUCCESS | K11: RUDRANI SENGUPTA | M11: 0 | N11: EDVIRON_EASEBUZZ | P11: 2 | Q11: FLAT | R11: 2 | S11: FLAT | T11: 0 | U11: FLAT
A12: 11 | B12: ST MICHAEL'S SCHOOL FOR GIRLS | C12: 30/11/2025, 2:29:11 pm | D12: SMED0000000337 | E12: 692c075f09edb37dee1521c4 | F12: 38100 | G12: 38102.36 | H12: upi | I12: Others | J12: SUCCESS | K12: VASUDHA ALOK | M12: 0 | N12: EDVIRON_EASEBUZZ | P12: 2 | Q12: FLAT | R12: 2 | S12: FLAT | T12: 0 | U12: FLAT
A13: 12 | B13: ST MICHAEL'S SCHOOL FOR GIRLS | C13: 1/12/2025, 1:41:08 PM | D13: SMED0000000339 | E13: 692d4d9c4b29e4e74d7d73d4 | F13: 10350 | G13: 10352.36 | H13: upi | I13: - | J13: SUCCESS | K13: SHRITI SHARMA | M13: 0 | N13: EDVIRON_EASEBUZZ | P13: 2 | Q13: FLAT | R13: 2 | S13: FLAT | T13: 0 | U13: FLAT
... A38: 37 | B38: ST MICHAEL'S SCHOOL FOR GIRLS | C38: 29/1/2026, 9:34:31 pm | D38: SMED0000000460 | E38: 697b850f0a91fbff417eab30 | F38: 34325 | G38: 34327.36 | H38: upi | I38: Others | J38: success | K38: AADHYA DAS | M38: 0 | N38: EDVIRON_EASEBUZZ | P38: 2 | Q38: FLAT | R38: 2 | S38: FLAT | T38: 0 | U38: FLAT

Sheet tbl_transactions
A1: Sl.No | B1: Institute Name | C1: Date & Time | D1: Date | E1: Time | F1: Edviron order ID | G1: Order Amt | H1: Transaction Amt | I1: Payment Method | J1: payment_mode | K1: Status | L1: Student Name | M1: Phone No. | N1: Vendor Amount | O1: Gateway | P1: Capture Status | Q1: Merchant Pricing | R1: Merchant Pricing Type | S1: Partner Pricing | T1: Partner Pricing Type | U1: Edviron Buying | V1: Edviron Buying type | W1: Merchant Pricing INR | X1: Partner Pricing INR | Y1: Edviron Buying INR | Z1: ERP Revenue | AA1: Edviron Net Revenue | AB1: Edviron Gross Revenue | AC1: Gateway Fee | AD1: Amount Payable to ERP | AE1: Amount Retained by Edviron
A2: 1 | B2: SBNM College of Pharmacy (D. Pharmacy & B.Pharmarcy | C2: 1/4/2025, 12:31:47 PM | D2: 45748 | E2: 12:31:47 PM | F2: 67eb8f5ba0b8c5db0650bf9c | G2: 3800 | H2: 3802.36 | I2: upi | J2: UPI | K2: SUCCESS | L2: RushikeshPatil | N2: 0 | O2: CASHFREE | P2: =K2 -> SUCCESS | Q2: 2 | R2: FLAT | S2: 2 | T2: FLAT | U2: 0 | V2: FLAT | W2: =IF(Table3[[#This Row],[Merchant Pricing Type]]="FLAT",Table3[[#This Row],[Merchant Pricing]],Table3[[#This Row],[Transaction Amt]]*Table3[[#This Row],[Merchant Pricing]]/100) -> 2 | X2: =IF(Table3[[#This Row],[Partner Pricing Type]]="FLAT",Table3[[#This Row],[Partner Pricing]],Table3[[#This Row],[Transaction Amt]]*Table3[[#This Row],[Partner Pricing]]/100) -> 2 | Y2: =IF(Table3[[#This Row],[Edviron Buying type]]="FLAT",Table3[[#This Row],[Edviron Buying]],Table3[[#This Row],[Transaction Amt]]*Table3[[#This Row],[Edviron Buying]]/100) -> 0 | Z2: =W2-X2 -> 0 | AA2: =X2-Y2 -> 2 | AB2: =Z2+AA2 -> 2 | AC2: =H2-N2 -> 3802.36 | AD2: =Z2 -> 0 | AE2: =AA2 -> 2
A3: 2 | B3: R P College of Pharmacy | C3: 11/4/2025, 11:51:49 AM | D3: 45778 | E3: 11:51:49 AM | F3: 67f8b4fdb7b5f003daf0968e | G3: 15000 | H3: 15002.36 | I3: upi | J3: UPI | K3: SUCCESS | L3: Pranav Prakash Deshpande | N3: 0 | O3: CASHFREE | P3: =K3 -> SUCCESS | Q3: 2 | R3: FLAT | S3: 2 | T3: FLAT | U3: 0 | V3: FLAT | W3: =IF(Table3[[#This Row],[Merchant Pricing Type]]="FLAT",Table3[[#This Row],[Merchant Pricing]],Table3[[#This Row],[Transaction Amt]]*Table3[[#This Row],[Merchant Pricing]]/100) -> 2 | X3: =IF(Table3[[#This Row],[Partner Pricing Type]]="FLAT",Table3[[#This Row],[Partner Pricing]],Table3[[#This Row],[Transaction Amt]]*Table3[[#This Row],[Partner Pricing]]/100) -> 2 | Y3: =IF(Table3[[#This Row],[Edviron Buying type]]="FLAT",Table3[[#This Row],[Edviron Buying]],Table3[[#This Row],[Transaction Amt]]*Table3[[#This Row],[Edviron Buying]]/100) -> 0 | Z3: =W3-X3 -> 0 | AA3: =X3-Y3 -> 2 | AB3: =Z3+AA3 -> 2 | AC3: =H3-N3 -> 15002.36 | AD3: =Z3 -> 0 | AE3: =AA3 -> 2
A4: 3 | B4: R P College of Pharmacy | C4: 21/4/2025, 10:31:19 am | D4: 45809 | E4: 10:31:19 am | F4: 6805d11f8218d3a8c0364231 | G4: 10000 | H4: 10002.36 | I4: upi | J4: UPI | K4: SUCCESS | L4: Dattatray Uttam Gholve | N4: 0 | O4: CASHFREE | P4: =K4 -> SUCCESS | Q4: 2 | R4: FLAT | S4: 2 | T4: FLAT | U4: 0 | V4: FLAT | W4: =IF(Table3[[#This Row],[Merchant Pricing Type]]="FLAT",Table3[[#This Row],[Merchant Pricing]],Table3[[#This Row],[Transaction Amt]]*Table3[[#This Row],[Merchant Pricing]]/100) -> 2 | X4: =IF(Table3[[#This Row],[Partner Pricing Type]]="FLAT",Table3[[#This Row],[Partner Pricing]],Table3[[#This Row],[Transaction Amt]]*Table3[[#This Row],[Partner Pricing]]/100) -> 2 | Y4: =IF(Table3[[#This Row],[Edviron Buying type]]="FLAT",Table3[[#This Row],[Edviron Buying]],Table3[[#This Row],[Transaction Amt]]*Table3[[#This Row],[Edviron Buying]]/100) -> 0 | Z4: =W4-X4 -> 0 | AA4: =X4-Y4 -> 2 | AB4: =Z4+AA4 -> 2 | AC4: =H4-N4 -> 10002.36 | AD4: =Z4 -> 0 | AE4: =AA4 -> 2
A5: 4 | B5: R P College of Pharmacy | C5: 29/4/2025, 11:10:54 am | D5: 45839 | E5: 11:10:54 am | F5: 681066668dde280c7a057a3a | G5: 5000 | H5: 5002.36 | I5: upi | J5: UPI | K5: SUCCESS | L5: Saniya Wajid Shaikh | N5: 0 | O5: CASHFREE | P5: =K5 -> SUCCESS | Q5: 2 | R5: FLAT | S5: 2 | T5: FLAT | U5: 0 | V5: FLAT | W5: =IF(Table3[[#This Row],[Merchant Pricing Type]]="FLAT",Table3[[#This Row],[Merchant Pricing]],Table3[[#This Row],[Transaction Amt]]*Table3[[#This Row],[Merchant Pricing]]/100) -> 2 | X5: =IF(Table3[[#This Row],[Partner Pricing Type]]="FLAT",Table3[[#This Row],[Partner Pricing]],Table3[[#This Row],[Transaction Amt]]*Table3[[#This Row],[Partner Pricing]]/100) -> 2 | Y5: =IF(Table3[[#This Row],[Edviron Buying type]]="FLAT",Table3[[#This Row],[Edviron Buying]],Table3[[#This Row],[Transaction Amt]]*Table3[[#This Row],[Edviron Buying]]/100) -> 0 | Z5: =W5-X5 -> 0 | AA5: =X5-Y5 -> 2 | AB5: =Z5+AA5 -> 2 | AC5: =H5-N5 -> 5002.36 | AD5: =Z5 -> 0 | AE5: =AA5 -> 2
A6: 5 | B6: R P College of Pharmacy | C6: 29/4/2025, 11:14:19 am | D6: 45870 | E6: 11:14:19 am | F6: 68106733d4b7fd07d305e50a | G6: 5000 | H6: 5002.36 | I6: upi | J6: UPI | K6: SUCCESS | L6: Pooja subhashprasad shukla | N6: 0 | O6: CASHFREE | P6: =K6 -> SUCCESS | Q6: 2 | R6: FLAT | S6: 2 | T6: FLAT | U6: 0 | V6: FLAT | W6: =IF(Table3[[#This Row],[Merchant Pricing Type]]="FLAT",Table3[[#This Row],[Merchant Pricing]],Table3[[#This Row],[Transaction Amt]]*Table3[[#This Row],[Merchant Pricing]]/100) -> 2 | X6: =IF(Table3[[#This Row],[Partner Pricing Type]]="FLAT",Table3[[#This Row],[Partner Pricing]],Table3[[#This Row],[Transaction Amt]]*Table3[[#This Row],[Partner Pricing]]/100) -> 2 | Y6: =IF(Table3[[#This Row],[Edviron Buying type]]="FLAT",Table3[[#This Row],[Edviron Buying]],Table3[[#This Row],[Transaction Amt]]*Table3[[#This Row],[Edviron Buying]]/100) -> 0 | Z6: =W6-X6 -> 0 | AA6: =X6-Y6 -> 2 | AB6: =Z6+AA6 -> 2 | AC6: =H6-N6 -> 5002.36 | AD6: =Z6 -> 0 | AE6: =AA6 -> 2
A7: 6 | B7: R P College of Pharmacy | C7: 30/4/2025, 1:53:35 pm | D7: 45901 | E7: 1:53:35 pm | F7: 6811de07d4b7fd07d306cb37 | G7: 10000 | H7: 10002.36 | I7: upi | J7: UPI | K7: SUCCESS | L7: BEGADE HALIMA BADSHAHA | N7: 0 | O7: CASHFREE | P7: =K7 -> SUCCESS | Q7: 2 | R7: FLAT | S7: 2 | T7: FLAT | U7: 0 | V7: FLAT | W7: =IF(Table3[[#This Row],[Merchant Pricing Type]]="FLAT",Table3[[#This Row],[Merchant Pricing]],Table3[[#This Row],[Transaction Amt]]*Table3[[#This Row],[Merchant Pricing]]/100) -> 2 | X7: =IF(Table3[[#This Row],[Partner Pricing Type]]="FLAT",Table3[[#This Row],[Partner Pricing]],Table3[[#This Row],[Transaction Amt]]*Table3[[#This Row],[Partner Pricing]]/100) -> 2 | Y7: =IF(Table3[[#This Row],[Edviron Buying type]]="FLAT",Table3[[#This Row],[Edviron Buying]],Table3[[#This Row],[Transaction Amt]]*Table3[[#This Row],[Edviron Buying]]/100) -> 0 | Z7: =W7-X7 -> 0 | AA7: =X7-Y7 -> 2 | AB7: =Z7+AA7 -> 2 | AC7: =H7-N7 -> 10002.36 | AD7: =Z7 -> 0 | AE7: =AA7 -> 2
A8: 7 | B8: R P College of Pharmacy | C8: 30/4/2025, 2:03:25 pm | D8: 45931 | E8: 2:03:25 pm | F8: 6811e055d4b7fd07d306ceed | G8: 18836 | H8: 18838.36 | I8: upi | J8: UPI | K8: SUCCESS | L8: JADHAV GAURAV SANTOSH | N8: 0 | O8: CASHFREE | P8: =K8 -> SUCCESS | Q8: 2 | R8: FLAT | S8: 2 | T8: FLAT | U8: 0 | V8: FLAT | W8: =IF(Table3[[#This Row],[Merchant Pricing Type]]="FLAT",Table3[[#This Row],[Merchant Pricing]],Table3[[#This Row],[Transaction Amt]]*Table3[[#This Row],[Merchant Pricing]]/100) -> 2 | X8: =IF(Table3[[#This Row],[Partner Pricing Type]]="FLAT",Table3[[#This Row],[Partner Pricing]],Table3[[#This Row],[Transaction Amt]]*Table3[[#This Row],[Partner Pricing]]/100) -> 2 | Y8: =IF(Table3[[#This Row],[Edviron Buying type]]="FLAT",Table3[[#This Row],[Edviron Buying]],Table3[[#This Row],[Transaction Amt]]*Table3[[#This Row],[Edviron Buying]]/100) -> 0 | Z8: =W8-X8 -> 0 | AA8: =X8-Y8 -> 2 | AB8: =Z8+AA8 -> 2 | AC8: =H8-N8 -> 18838.36 | AD8: =Z8 -> 0 | AE8: =AA8 -> 2
A9: 8 | B9: R P College of Pharmacy | C9: 14/6/2025, 11:24:42 am | D9: 45962 | E9: 11:24:42 am | F9: 684d0ea2b1091c01feb8de58 | G9: 10576 | H9: 10578.36 | I9: upi | J9: Others | K9: SUCCESS | L9: SOHAM SAGAR KHOT | N9: 0 | O9: CASHFREE | P9: =K9 -> SUCCESS | Q9: 2 | R9: FLAT | S9: 2 | T9: FLAT | U9: 0 | V9: FLAT | W9: =IF(Table3[[#This Row],[Merchant Pricing Type]]="FLAT",Table3[[#This Row],[Merchant Pricing]],Table3[[#This Row],[Transaction Amt]]*Table3[[#This Row],[Merchant Pricing]]/100) -> 2 | X9: =IF(Table3[[#This Row],[Partner Pricing Type]]="FLAT",Table3[[#This Row],[Partner Pricing]],Table3[[#This Row],[Transaction Amt]]*Table3[[#This Row],[Partner Pricing]]/100) -> 2 | Y9: =IF(Table3[[#This Row],[Edviron Buying type]]="FLAT",Table3[[#This Row],[Edviron Buying]],Table3[[#This Row],[Transaction Amt]]*Table3[[#This Row],[Edviron Buying]]/100) -> 0 | Z9: =W9-X9 -> 0 | AA9: =X9-Y9 -> 2 | AB9: =Z9+AA9 -> 2 | AC9: =H9-N9 -> 10578.36 | AD9: =Z9 -> 0 | AE9: =AA9 -> 2
A10: 9 | B10: R P College of Pharmacy | C10: 7/7/2025, 4:08:10 PM | D10: 45992 | E10: 4:08:10 PM | F10: 686ba3924e76b124b7acdd57 | G10: 1 | H10: 3.36 | I10: upi | J10: Others | K10: SUCCESS | L10: Test Student | N10: 0 | O10: CASHFREE | P10: =K10 -> SUCCESS | Q10: 2 | R10: FLAT | S10: 2 | T10: FLAT | U10: 0 | V10: FLAT | W10: =IF(Table3[[#This Row],[Merchant Pricing Type]]="FLAT",Table3[[#This Row],[Merchant Pricing]],Table3[[#This Row],[Transaction Amt]]*Table3[[#This Row],[Merchant Pricing]]/100) -> 2 | X10: =IF(Table3[[#This Row],[Partner Pricing Type]]="FLAT",Table3[[#This Row],[Partner Pricing]],Table3[[#This Row],[Transaction Amt]]*Table3[[#This Row],[Partner Pricing]]/100) -> 2 | Y10: =IF(Table3[[#This Row],[Edviron Buying type]]="FLAT",Table3[[#This Row],[Edviron Buying]],Table3[[#This Row],[Transaction Amt]]*Table3[[#This Row],[Edviron Buying]]/100) -> 0 | Z10: =W10-X10 -> 0 | AA10: =X10-Y10 -> 2 | AB10: =Z10+AA10 -> 2 | AC10: =H10-N10 -> 3.36 | AD10: =Z10 -> 0 | AE10: =AA10 -> 2
A11: 10 | B11: ST MICHAEL'S SCHOOL FOR GIRLS | C11: 14/11/2025, 10:46:26 am | D11: 45670 | E11: 10:46:26 am | F11: 6916bb2afede88bc173e1480 | G11: 34325 | H11: 34327.36 | I11: upi | J11: Others | K11: SUCCESS | L11: RUDRANI SENGUPTA | N11: 0 | O11: EDVIRON_EASEBUZZ | P11: =K11 -> SUCCESS | Q11: 2 | R11: FLAT | S11: 2 | T11: FLAT | U11: 0 | V11: FLAT | W11: =IF(Table3[[#This Row],[Merchant Pricing Type]]="FLAT",Table3[[#This Row],[Merchant Pricing]],Table3[[#This Row],[Transaction Amt]]*Table3[[#This Row],[Merchant Pricing]]/100) -> 2 | X11: =IF(Table3[[#This Row],[Partner Pricing Type]]="FLAT",Table3[[#This Row],[Partner Pricing]],Table3[[#This Row],[Transaction Amt]]*Table3[[#This Row],[Partner Pricing]]/100) -> 2 | Y11: =IF(Table3[[#This Row],[Edviron Buying type]]="FLAT",Table3[[#This Row],[Edviron Buying]],Table3[[#This Row],[Transaction Amt]]*Table3[[#This Row],[Edviron Buying]]/100) -> 0 | Z11: =W11-X11 -> 0 | AA11: =X11-Y11 -> 2 | AB11: =Z11+AA11 -> 2 | AC11: =H11-N11 -> 34327.36 | AD11: =Z11 -> 0 | AE11: =AA11 -> 2
A12: 11 | B12: ST MICHAEL'S SCHOOL FOR GIRLS | C12: 30/11/2025, 2:29:11 pm | D12: 45671 | E12: 2:29:11 pm | F12: 692c075f09edb37dee1521c4 | G12: 38100 | H12: 38102.36 | I12: upi | J12: Others | K12: SUCCESS | L12: VASUDHA ALOK | N12: 0 | O12: EDVIRON_EASEBUZZ | P12: =K12 -> SUCCESS | Q12: 2 | R12: FLAT | S12: 2 | T12: FLAT | U12: 0 | V12: FLAT | W12: =IF(Table3[[#This Row],[Merchant Pricing Type]]="FLAT",Table3[[#This Row],[Merchant Pricing]],Table3[[#This Row],[Transaction Amt]]*Table3[[#This Row],[Merchant Pricing]]/100) -> 2 | X12: =IF(Table3[[#This Row],[Partner Pricing Type]]="FLAT",Table3[[#This Row],[Partner Pricing]],Table3[[#This Row],[Transaction Amt]]*Table3[[#This Row],[Partner Pricing]]/100) -> 2 | Y12: =IF(Table3[[#This Row],[Edviron Buying type]]="FLAT",Table3[[#This Row],[Edviron Buying]],Table3[[#This Row],[Transaction Amt]]*Table3[[#This Row],[Edviron Buying]]/100) -> 0 | Z12: =W12-X12 -> 0 | AA12: =X12-Y12 -> 2 | AB12: =Z12+AA12 -> 2 | AC12: =H12-N12 -> 38102.36 | AD12: =Z12 -> 0 | AE12: =AA12 -> 2
A13: 12 | B13: ST MICHAEL'S SCHOOL FOR GIRLS | C13: 1/12/2025, 1:41:08 PM | D13: 45672 | E13: 1:41:08 PM | F13: 692d4d9c4b29e4e74d7d73d4 | G13: 10350 | H13: 10352.36 | I13: upi | J13: - | K13: SUCCESS | L13: SHRITI SHARMA | N13: 0 | O13: EDVIRON_EASEBUZZ | P13: =K13 -> SUCCESS | Q13: 2 | R13: FLAT | S13: 2 | T13: FLAT | U13: 0 | V13: FLAT | W13: =IF(Table3[[#This Row],[Merchant Pricing Type]]="FLAT",Table3[[#This Row],[Merchant Pricing]],Table3[[#This Row],[Transaction Amt]]*Table3[[#This Row],[Merchant Pricing]]/100) -> 2 | X13: =IF(Table3[[#This Row],[Partner Pricing Type]]="FLAT",Table3[[#This Row],[Partner Pricing]],Table3[[#This Row],[Transaction Amt]]*Table3[[#This Row],[Partner Pricing]]/100) -> 2 | Y13: =IF(Table3[[#This Row],[Edviron Buying type]]="FLAT",Table3[[#This Row],[Edviron Buying]],Table3[[#This Row],[Transaction Amt]]*Table3[[#This Row],[Edviron Buying]]/100) -> 0 | Z13: =W13-X13 -> 0 | AA13: =X13-Y13 -> 2 | AB13: =Z13+AA13 -> 2 | AC13: =H13-N13 -> 10352.36 | AD13: =Z13 -> 0 | AE13: =AA13 -> 2
... A38: 37 | B38: ST MICHAEL'S SCHOOL FOR GIRLS | C38: 29/1/2026, 9:34:31 pm | D38: 45902 | E38: 9:34:31 pm | F38: 697b850f0a91fbff417eab30 | G38: 34325 | H38: 34327.36 | I38: upi | J38: Others | K38: SUCCESS | L38: AADHYA DAS | N38: 0 | O38: EDVIRON_EASEBUZZ | P38: =K38 -> SUCCESS | Q38: 2 | R38: FLAT | S38: 2 | T38: FLAT | U38: 0 | V38: FLAT | W38: =IF(Table3[[#This Row],[Merchant Pricing Type]]="FLAT",Table3[[#This Row],[Merchant Pricing]],Table3[[#This Row],[Transaction Amt]]*Table3[[#This Row],[Merchant Pricing]]/100) -> 2 | X38: =IF(Table3[[#This Row],[Partner Pricing Type]]="FLAT",Table3[[#This Row],[Partner Pricing]],Table3[[#This Row],[Transaction Amt]]*Table3[[#This Row],[Partner Pricing]]/100) -> 2 | Y38: =IF(Table3[[#This Row],[Edviron Buying type]]="FLAT",Table3[[#This Row],[Edviron Buying]],Table3[[#This Row],[Transaction Amt]]*Table3[[#This Row],[Edviron Buying]]/100) -> 0 | Z38: =W38-X38 -> 0 | AA38: =X38-Y38 -> 2 | AB38: =Z38+AA38 -> 2 | AC38: =H38-N38 -> 34327.36 | AD38: =Z38 -> 0 | AE38: =AA38 -> 2

Sheet Revenue_Summary
A3: Date | B3: Count of Edviron order ID | C3: Sum of Transaction Amt | D3: Sum of ERP Revenue | E3: Sum of Edviron Net Revenue | F3: Sum of Edviron Gross Revenue
A4: (blank)
A5: 2-Jan | B5: 1 | C5: 34327.36 | D5: 0 | E5: 2 | F5: 2
A6: 13-Jan | B6: 1 | C6: 34327.36 | D6: 0 | E6: 2 | F6: 2
A7: 14-Jan | B7: 1 | C7: 38102.36 | D7: 0 | E7: 2 | F7: 2
A8: 15-Jan | B8: 1 | C8: 10352.36 | D8: 0 | E8: 2 | F8: 2
A9: 16-Jan | B9: 1 | C9: 10952.36 | D9: 0 | E9: 2 | F9: 2
A10: 17-Jan | B10: 1 | C10: 10352.36 | D10: 0 | E10: 2 | F10: 2
A11: 18-Jan | B11: 1 | C11: 10952.36 | D11: 0 | E11: 2 | F11: 2
A12: 19-Jan | B12: 1 | C12: 74152.36 | D12: 0 | E12: 2 | F12: 2
A13: 20-Jan | B13: 1 | C13: 10352.36 | D13: 0 | E13: 2 | F13: 2
A14: 21-Jan | B14: 1 | C14: 10352.36 | D14: 0 | E14: 2 | F14: 2
A15: 22-Jan | B15: 1 | C15: 34327.36 | D15: 0 | E15: 2 | F15: 2
A16: 23-Jan | B16: 1 | C16: 10952.36 | D16: 0 | E16: 2 | F16: 2
... A42: Grand Total | B42: 37 | C42: 892475.32 | D42: 0 | E42: 74 | F42: 74

Sheet Partner_Performance
A3: Institute Name | B3: Count of Edviron order ID | C3: Sum of Transaction Amt | D3: Sum of ERP Revenue | E3: Sum of Edviron Net Revenue | F3: Sum of Edviron Gross Revenue | H3: Average take rate
A4: R P College of Pharmacy | B4: 8 | C4: 74431.88 | D4: 0 | E4: 16 | F4: 16 | H4: =GETPIVOTDATA("Sum of Edviron Gross Revenue",$A$3)/GETPIVOTDATA("Sum of Transaction Amt",$A$3) -> 8.2915458e-05
A5: SBNM College of Pharmacy (D. Pharmacy & B.Pharmarcy | B5: 1 | C5: 3802.36 | D5: 0 | E5: 2 | F5: 2
A6: ST MICHAEL'S SCHOOL FOR GIRLS | B6: 28 | C6: 814241.08 | D6: 0 | E6: 56 | F6: 56
A7: (blank)
A8: Grand Total | B8: 37 | C8: 892475.32 | D8: 0 | E8: 74 | F8: 74

Sheet Gateway_Analysis
A3: Gateway | B3: payment_mode | C3: Sum of Transaction Amt | D3: Count of Edviron order ID | E3: Sum of ERP Revenue
A4: CASHFREE | C4: 78234.24 | D4: 9 | E4: 0
B5: Others | C5: 10581.72 | D5: 2 | E5: 0
B6: UPI | C6: 67652.52 | D6: 7 | E6: 0
A7: EDVIRON_EASEBUZZ | C7: 814241.08 | D7: 28 | E7: 0
B8: - | C8: 155943.88 | D8: 8 | E8: 0
B9: Others | C9: 658297.2 | D9: 20 | E9: 0
A10: (blank)
A11: Grand Total | C11: 892475.32 | D11: 37 | E11: 0
A14: Status | B14: Count of Edviron order ID
A15: SUCCESS | B15: 1 | D15: Success Rate
A16: (blank) | B16: 0 | D16: =GETPIVOTDATA("Edviron order ID",$A$14)/GETPIVOTDATA("Edviron order ID",$A$14) -> 1
A17: Grand Total | B17: 1

Sheet Exposure_Report
A3: Status | B3: Capture Status | C3: Institute Name | D3: Sum of Amount Payable to ERP | E3: Sum of Edviron Net Revenue
A4: SUCCESS | D4: 0 | E4: 74
B5: SUCCESS | D5: 0 | E5: 74
C6: R P College of Pharmacy | D6: 0 | E6: 16
C7: SBNM College of Pharmacy (D. Pharmacy & B.Pharmarcy | D7: 0 | E7: 2
C8: ST MICHAEL'S SCHOOL FOR GIRLS | D8: 0 | E8: 56
A9: Grand Total | D9: 0 | E9: 74

Sheet Modeling
D1: {=_xlfn.UNIQUE(tbl_transactions!B1:B38)} -> Institute Name | E1: {=_xlfn.UNIQUE(tbl_transactions!O1:O38)} -> Gateway | F1: {=_xlfn.UNIQUE(tbl_transactions!I1:I38)} -> Payment Method
A2: Start Date | B2: 45870 | D2: SBNM College of Pharmacy (D. Pharmacy & B.Pharmarcy | E2: CASHFREE | F2: upi | J2: Revenue Split
A3: End Date | B3: 45931 | D3: R P College of Pharmacy | E3: EDVIRON_EASEBUZZ | F3: - | J3: Type | K3: Value
A4: Selected ERP | B4: ST MICHAEL'S SCHOOL FOR GIRLS | D4: ST MICHAEL'S SCHOOL FOR GIRLS | E4: {=_xlfn.VSTACK("ALL",E2:E3)} -> ALL | J4: ERP | K4: =C12 -> 0
A5: Selected Gateway | B5: EDVIRON_EASEBUZZ | D5: {=_xlfn.VSTACK("ALL",D2:D4)} -> ALL | E5: CASHFREE | J5: Edviron | K5: =D12 -> 2
A6: Selected Payment Method | B6: upi | D6: SBNM College of Pharmacy (D. Pharmacy & B.Pharmarcy | E6: EDVIRON_EASEBUZZ
D7: R P College of Pharmacy
D8: ST MICHAEL'S SCHOOL FOR GIRLS
A11: Total Transactions | B11: Total GMV | C11: ERP Revenue | D11: {=tbl_transactions!AA1:AA38} -> Edviron Net Revenue | E11: {=tbl_transactions!AB1:AB38} -> Edviron Gross Revenue | F11: Pending Exposure | G11: Unique Users | H11: Payment Frequency
A12: {=COUNTIFS(tbl_transactions!K1:K38,"SUCCESS",tbl_transactions!D1:D38,">="&B2,tbl_transactions!D1:D38,"<="&B3,tbl_transactions!B1:B38,IF(B4="All",tbl_transactions!B1:B38,B4),tbl_transactions!O1:O38,IF(B5="All",tbl_transactions!O1:O38,B5),tbl_transactions!I1:I38,IF(B6="All",tbl_transactions!I1:I38,B6))} -> 2 | B12: {=SUMIFS(tbl_transactions!H1:H38,tbl_transactions!K1:K38,"SUCCESS",tbl_transactions!D1:D38,">="&B2,tbl_transactions!D1:D38,"<="&B3,tbl_transactions!B1:B38,IF(B4="All",tbl_transactions!B1:B38,B4),tbl_transactions!O1:O38,IF(B5="All",tbl_transactions!O1:O38,B5),tbl_transactions!I1:I38,IF(B6="All",tbl_transactions!I1:I38,B6))} -> 68654.72 | C12: {=SUMIFS(tbl_transactions!Z1:Z38,tbl_transactions!K1:K38,"SUCCESS",tbl_transactions!D1:D38,">="&B2,tbl_transactions!D1:D38,"<="&B3,tbl_transactions!B1:B38,IF(B4="All",tbl_transactions!B1:B38,B4),tbl_transactions!O1:O38,IF(B5="All",tbl_transactions!O1:O38,B5),tbl_transactions!I1:I38,IF(B6="All",tbl_transactions!I1:I38,B6))} -> 0 | D12: 2 | E12: 2 | F12: =SUMIFS(tbl_transactions!H1:H38,tbl_transactions!K1:K38,"<>SUCCESS",tbl_transactions!D1:D38,">="&B2,tbl_transactions!D1:D38,"<="&B3) -> 0 | G12: {=COUNTA(_xlfn.UNIQUE(_xlfn._xlws.FILTER(tbl_transactions!L1:L38,tbl_transactions!K1:K38="SUCCESS")))} -> 36 | H12: =B12/G12 -> 1907.0756
D13: 2 | E13: 2
D14: 2 | E14: 2
D15: 2 | E15: 2
D16: 2 | E16: 2
D17: 2 | E17: 2
D18: 2 | E18: 2
D19: 2 | E19: 2
D20: 2 | E20: 2
D21: 2 | E21: 2
D22: 2 | E22: 2
D23: 2 | E23: 2
D24: 2 | E24: 2
... D48: 2 | E48: 2

Sheet Dashboard
A1: Start Date | B1: =Modeling!B2 -> 45870 | C1: Total Transactions | F1: Total GMV
A2: End Date | B2: =Modeling!B3 -> 45931 | C2: =Modeling!A12 -> 2 | F2: =Modeling!B12 -> 68654.72
A3: ERP | B3: =Modeling!B4 -> ST MICHAEL'S SCHOOL FOR GIRLS
A4: Gateway | B4: =Modeling!B5 -> EDVIRON_EASEBUZZ | C4: Gateway | D4: Gateway-wise contribution | F4: Institute Name | G4: Sum of Transaction Amt | I4: Date | J4: Time-based trend (Daily / Monthly)
A5: Payment Method | B5: =Modeling!B6 -> upi | C5: CASHFREE | D5: 78234.24 | F5: R P College of Pharmacy | G5: 74431.88 | I5: 2-Jan | J5: 2
A6: Total Transactions | B6: =Modeling!A12 -> 2 | C6: EDVIRON_EASEBUZZ | D6: 814241.08 | F6: SBNM College of Pharmacy (D. Pharmacy & B.Pharmarcy | G6: 3802.36 | I6: 13-Jan | J6: 2
A7: Total GMV | B7: =Modeling!B12 -> 68654.72 | C7: Grand Total | D7: 892475.32 | F7: ST MICHAEL'S SCHOOL FOR GIRLS | G7: 814241.08 | I7: 14-Jan | J7: 2
A8: ERP Revenue | B8: =Modeling!C12 -> 0 | F8: Grand Total | G8: 892475.32 | I8: 15-Jan | J8: 2
A9: Edviron Net Revenue | B9: =Modeling!D12 -> 2 | C9: Payment Method | D9: Total Transactions | I9: 16-Jan | J9: 2
A10: Edviron Gross Revenue | B10: =Modeling!E12 -> 2 | C10: upi | D10: 892475.32 | I10: 17-Jan | J10: 2
A11: Pending Exposure | B11: =Modeling!F12 -> 0 | C11: Grand Total | D11: 892475.32 | I11: 18-Jan | J11: 2
A12: Unique Users | B12: =Modeling!G12 -> 36 | I12: 19-Jan | J12: 2
A13: Frequency | B13: =Modeling!H12 -> 1907.0756 | I13: 20-Jan | J13: 2
I14: 21-Jan | J14: 2
I15: 22-Jan | J15: 2
I16: 23-Jan | J16: 2
I17: 24-Jan | J17: 2
I18: 25-Jan | J18: 2
I19: 26-Jan | J19: 2
I20: 27-Jan | J20: 2
I21: 28-Jan | J21: 2
I22: 29-Jan | J22: 2
I23: 30-Jan | J23: 2
I24: 31-Jan | J24: 2
I25: 2-Feb | J25: 2
... I42: Grand Total | J42: 74

Sheet Assumptions_Notes
A1: Explanation
A2: Interactive Revenue Dashboard
A3: 1. Revenue Logic Explanation | B3: 2. Assumptions Made | C3: 3. Dashboard Design Rationale | D3: 4. Dynamic Behaviour | E3: Conclusion
A5: The dashboard is built using a structured data flow: | B5: Only "SUCCESS" transactions contribute to revenue and GMV. | C5: The dashboard is designed for clarity, decision-making, and executive readability. | D5: All KPIs use modelling sheet formulas (COUNTIFS, SUMIFS). | E5: This interactive dashboard provides a structured view of:
D6: All charts are linked to pivot tables based on tbl_transactions.
A7: Raw Data (tbl_transactions) → Modelling Sheet → Dashboard | B7: "PENDING" transactions contribute to exposure but not revenue. | C7: A. Layout Structure | D7: Slicers are connected to all pivot tables using Report Connections. | E7: • Revenue performance
E8: • Partner contribution
A9: A. Total Transactions | B9: Commission percentages remain constant during selected date range. | C9: Top Section: | D9: This ensures: | E9: • Gateway impact
E10: • User behavior
A11: Calculated using: | B11: Gateway charges are applied per transaction consistently. | C11: Date range selector | D11: Any filter change updates entire dashboard automatically. | E11: • Financial exposure
A12: COUNTIFS formula based on:
B13: Each User ID represents a unique customer. | C13: ERP filter | D13: No manual data adjustments required. | E13: The model is fully dynamic, scalable, and suitable for performance evaluation and management reporting.
A14: Date range (Start Date & End Date)
B15: No duplicate transactions exist in cleaned dataset. | C15: Gateway filter | D15: Dashboard reflects real-time filtered insights.
A16: Selected ERP (Institute Name)
B17: Date grouping for trends is based on transaction date. | C17: Payment method filter
A18: Selected Gateway
C19: This allows dynamic slicing of data.
A20: Selected Payment Method
C21: Second Section:
A22: Status = "SUCCESS"
C23: KPI Tiles
A24: This ensures only valid successful transactions are included.
C25: Displays high-level metrics for quick review.
A26: B. Total GMV (Gross Merchandise Value)
C27: Middle Section:
A28: Calculated using:
A29: SUMIFS on Transaction Amount column. | C29: Revenue Split (Donut Chart)
C30: → Shows distribution between ERP and Edviron.
A31: Filters applied:
C32: Time Trend (Line Chart)
A33: Date range | C33: → Identifies seasonal patterns and growth.
A35: ERP selection | C35: Bottom Section:
A37: Gateway | C37: Gateway Contribution (Column Chart)
C38: → Shows which gateway drives most volume.
A39: Payment Method
C40: Payment Method Mix (Pie Chart)
A41: Status = "SUCCESS" | C41: → Displays customer payment preference.
A43: GMV represents the total payment volume processed. | C43: B. Design Principles Used
A45: C. ERP Revenue | C45: • Clean layout (no gridlines)
...
